Workbook

Sheet Artists
A1: ConstituentID | B1: DisplayName | C1: ArtistBio | D1: Nationality | E1: Gender | F1: BeginDate | G1: EndDate
A2: 11 | B2: Jean (Hans) Arp | C2: French, born Germany (Alsace). 1886–1966 | D2: French | E2: male | F2: 1886 | G2: 1966
A3: 19 | B3: Richard Artschwager | C3: American, 1923–2013 | D3: American | E3: male | F3: 1923 | G3: 2013
A4: 34 | B4: Alvar Aalto | C4: Finnish, 1898–1976 | D4: Finnish | E4: male | F4: 1898 | G4: 1976
A5: 38 | B5: Magdalena Abakanowicz | C5: Polish, 1930–2017 | D5: Polish | E5: female | F5: 1930 | G5: 2017
A6: 60 | B6: Ansel Adams | C6: American, 1902–1984 | D6: American | E6: male | F6: 1902 | G6: 1984
A7: 94 | B7: Munira Al-Kazi | C7: Kuwaiti, born 1939 | D7: Kuwaiti | E7: female | F7: 1939 | G7: 0
A8: 140 | B8: Jim Amaral | C8: American, born 1933 | D8: American | E8: male | F8: 1933 | G8: 0
A9: 144 | B9: Woody van Amen | C9: Dutch, born 1936 | D9: Dutch | E9: male | F9: 1936 | G9: 0
A10: 153 | B10: Emma Amos | C10: American, 1937–2020 | D10: American | E10: female | F10: 1937 | G10: 2020
A11: 159 | B11: Gunnar Aagaard Andersen | C11: Danish, 1919–1982 | D11: Danish | E11: male | F11: 1919 | G11: 1982
A12: 208 | B12: Diane Arbus | C12: American, 1923–1971 | D12: American | E12: female | F12: 1923 | G12: 1971
A13: 229 | B13: Eugène Atget | C13: French, 1857–1927 | D13: French | E13: male | F13: 1857 | G13: 1927
... A60: 1247 | B60: Joseph Cornell | C60: American, 1903–1972 | D60: American | E60: male | F60: 1903 | G60: 1972
A61: 1249 | B61: Corning Glass Works, Corning, NY | C61: est. 1851 | D61: American | F61: 1851 | G61: 0
A62: 1300 | B62: Robert Creeley | C62: American, 1926–2005 | D62: American | E62: male | F62: 1926 | G62: 2005
A63: 1330 | B63: Robert Cumming | C63: American, 1943–2021 | D63: American | E63: male | F63: 1943 | G63: 2021
A64: 1332 | B64: Imogen Cunningham | C64: American, 1883–1976 | D64: American | E64: female | F64: 1883 | G64: 1976
A65: 1364 | B65: Salvador Dalí | C65: Spanish, 1904–1989 | D65: Spanish | E65: male | F65: 1904 | G65: 1989
A66: 1391 | B66: Sandu Darie | C66: Cuban, born Romania. 1908–1991 | D66: Cuban | E66: male | F66: 1908 | G66: 1991
A67: 1402 | B67: Arthur B. Davies | C67: American, 1862–1928 | D67: American | E67: male | F67: 1862 | G67: 1928
A68: 1422 | B68: Roy DeCarava | C68: American, 1919–2009 | D68: American | E68: male | F68: 1919 | G68: 2009
A69: 1438 | B69: Jonathan De Pas | C69: Italian, 1932–1991 | D69: Italian | E69: male | F69: 1932 | G69: 1991
A70: 1444 | B70: Niki de Saint Phalle | C70: French and American, 1930–2002 | D70: French | E70: female | F70: 1930 | G70: 2002
A71: 1467 | B71: Dorothy Dehner | C71: American, 1901–1994 | D71: American | E71: female | F71: 1901 | G71: 1994
A72: 1475 | B72: Jack Delano | C72: American, born Russia. 1914–1997 | D72: American | E72: male | F72: 1914 | G72: 1997
A73: 1479 | B73: Robert Delaunay | C73: French, 1885–1941 | D73: French | E73: male | F73: 1885 | G73: 1941
... A281: 5702 | B281: Michelle Stuart | C281: American, born 1938 | D281: American | E281: female | F281: 1938 | G281: 0
A282: 5707 | B282: Studio Opi | C282: Italian, established 1955 | D282: Italian | F282: 1955 | G282: 0
A283: 5719 | B283: Kumi Sugaï | C283: Japanese, 1919–1996 | D283: Japanese | E283: male | F283: 1919 | G283: 1996
A284: 5723 | B284: Louis Sullivan | C284: American, 1856–1924 | D284: American | E284: male | F284: 1856 | G284: 1924
A285: 5749 | B285: Luke Swank | C285: American, 1890–1944 | D285: American | E285: male | F285: 1890 | G285: 1944
A286: 5777 | B286: Sophie Taeuber-Arp | C286: French, born Switzerland. 1889–1943 | D286: Swiss | E286: female | F286: 1889 | G286: 1943
A287: 5799 | B287: Atsuko Tanaka | C287: Japanese, 1932–2005 | D287: Japanese | E287: female | F287: 1932 | G287: 2005
A288: 5806 | B288: Dorothea Tanning | C288: American, 1910–2012 | D288: American | E288: female | F288: 1910 | G288: 2012
A289: 5809 | B289: Antoni Tàpies | C289: Spanish, 1923–2012 | D289: Spanish | E289: male | F289: 1923 | G289: 2012
A290: 5814 | B290: Lenore Tawney | C290: American, 1907–2007 | D290: American | E290: female | F290: 1907 | G290: 2007
A291: 5858 | B291: Bob Thompson | C291: American, 1937–1966 | D291: American | E291: male | F291: 1937 | G291: 1966
A292: 5882 | B292: Jean Tinguely | C292: Swiss, 1925–1991 | D292: Swiss | E292: male | F292: 1925 | G292: 1991
A293: 5907 | B293: Joaquín Torres-García | C293: Uruguayan, 1874–1949 | D293: Uruguayan | E293: male | F293: 1874 | G293: 1949
...

Sheet Artworks
A1: ObjectID | B1: Title | C1: ConstituentID | D1: Artists | E1: Date | F1: Clean Date | G1: Medium | H1: Dimensions | I1: Classification | J1: Department | K1: DateAcquired | L1: URL | M1: ImageURL | N1: OnView
A2: 257 | B2: Simulated Dwelling for a Family of Five Project | C2: 2864 | D2: {=_xlfn.TEXTJOIN(",",TRUE,_xlfn.XLOOKUP(_xlfn.TEXTSPLIT(C2,",")*1,_xlfn._TRO_TRAILING(Artists!A:A),_xlfn._TRO_TRAILING(Artists!B:B)))} -> David Jacob | E2: 1970 | F2: {=_xlfn.REGEXEXTRACT(E2,"\d{4}")*1} -> 1970 | G2: Fiberglass, polyester resin, metal, paper, plastic and synthetic polymer paint | H2: 28 x 34 3/8 x 34 3/8" (71.1 x 87.3 x 87.3 cm) | I2: Architecture | J2: Architecture & Design | K2: 26792 | L2: https://www.moma.org/collection/works/257 | M2: https://www.moma.org/media/W1siZiIsIjIyODY1OCJdLFsicCIsImNvbnZlcnQiLCItcmVzaXplIDEwMjR4MTAyNFx1MDAzZSJdXQ.jpg?sha=0f4261daac246e9b | N2: Floor 4, 417
A3: 775 | B3: Concrete Office Building Project, Berlin, Germany (Exterior perspective) | C3: 7166 | D3: {=_xlfn.TEXTJOIN(",",TRUE,_xlfn.XLOOKUP(_xlfn.TEXTSPLIT(C3,",")*1,_xlfn._TRO_TRAILING(Artists!A:A),_xlfn._TRO_TRAILING(Artists!B:B)))} -> Ludwig Mies van der Rohe | E3: 1923 | F3: {=_xlfn.REGEXEXTRACT(E3,"\d{4}")*1} -> 1923 | G3: Charcoal and crayon on paper | H3: 54 1/2 x 113 3/4" (138.4 x 288.9 cm) | I3: Mies van der Rohe Archive | J3: Architecture & Design | K3: 24904 | L3: https://www.moma.org/collection/works/775 | M3: https://www.moma.org/media/W1siZiIsIjQwMDE2MSJdLFsicCIsImNvbnZlcnQiLCItcmVzaXplIDEwMjR4MTAyNFx1MDAzZSJdXQ.jpg?sha=110180447018c67d | N3: Floor 5, 511
A4: 941 | B4: Furniture Manufacturers Association Headquarters, project, High Wycombe, England, Side elevation | C4: 7987 | D4: {=_xlfn.TEXTJOIN(",",TRUE,_xlfn.XLOOKUP(_xlfn.TEXTSPLIT(C4,",")*1,_xlfn._TRO_TRAILING(Artists!A:A),_xlfn._TRO_TRAILING(Artists!B:B)))} -> Michael Webb | E4: 1957-58 | F4: {=_xlfn.REGEXEXTRACT(E4,"\d{4}")*1} -> 1957 | G4: Graphite and ink on tracing paper mounted on board | H4: 23 1/2 x 32" (59.7 x 81.3 cm) | I4: Architecture | J4: Architecture & Design | K4: 36111 | L4: https://www.moma.org/collection/works/941 | M4: https://www.moma.org/media/W1siZiIsIjUzMDIyMSJdLFsicCIsImNvbnZlcnQiLCItcmVzaXplIDEwMjR4MTAyNFx1MDAzZSJdXQ.jpg?sha=2964904217fe93e6 | N4: Floor 4, 417
A5: 1007 | B5: Column Cover for the German Pavilion, International Exposition, Barcelona, Spain | C5: 7166 | D5: {=_xlfn.TEXTJOIN(",",TRUE,_xlfn.XLOOKUP(_xlfn.TEXTSPLIT(C5,",")*1,_xlfn._TRO_TRAILING(Artists!A:A),_xlfn._TRO_TRAILING(Artists!B:B)))} -> Ludwig Mies van der Rohe | E5: 1928-29 | F5: {=_xlfn.REGEXEXTRACT(E5,"\d{4}")*1} -> 1928 | G5: Chrome-plated steel | H5: 118 1/2 x 6 1/2 x 6 1/2" (301 x 16.5 x 16.5 cm) | I5: Architecture | J5: Architecture & Design | K5: 31692 | L5: https://www.moma.org/collection/works/1007 | M5: https://www.moma.org/media/W1siZiIsIjIxMDkyNSJdLFsicCIsImNvbnZlcnQiLCItcmVzaXplIDEwMjR4MTAyNFx1MDAzZSJdXQ.jpg?sha=f09f4ba416d3a81e | N5: Floor 5, 511
A6: 1512 | B6: Carna Folding Wheelchair | C6: 7440 | D6: {=_xlfn.TEXTJOIN(",",TRUE,_xlfn.XLOOKUP(_xlfn.TEXTSPLIT(C6,",")*1,_xlfn._TRO_TRAILING(Artists!A:A),_xlfn._TRO_TRAILING(Artists!B:B)))} -> Kazuo Kawasaki | E6: 1989 | F6: {=_xlfn.REGEXEXTRACT(E6,"\d{4}")*1} -> 1989 | G6: Titanium, rubber, and aluminum honeycomb | H6: 33 x 22 x 35 1/4" (83.8 x 55.9 x 89.5 cm) | I6: Design | J6: Architecture & Design | K6: 34716 | L6: https://www.moma.org/collection/works/1512 | M6: https://www.moma.org/media/W1siZiIsIjIxMDAyMSJdLFsicCIsImNvbnZlcnQiLCItcmVzaXplIDEwMjR4MTAyNFx1MDAzZSJdXQ.jpg?sha=3b7076d407aab09b | N6: Floor 4, 417
A7: 1621 | B7: Mind Expander / Flyhead Helmet | C7: 8412, 8413, 7561, 8414, 7562 | D7: {=_xlfn.TEXTJOIN(",",TRUE,_xlfn.XLOOKUP(_xlfn.TEXTSPLIT(C7,",")*1,_xlfn._TRO_TRAILING(Artists!A:A),_xlfn._TRO_TRAILING(Artists!B:B)))} -> Haus-Rucker-Co,Günter Zamp Kelp,Laurids Ortner,Klaus Pinter,Manfred Ortner | E7: 1968 | F7: {=_xlfn.REGEXEXTRACT(E7,"\d{4}")*1} -> 1968 | M7: https://www.moma.org/media/W1siZiIsIjQyMDk5MSJdLFsicCIsImNvbnZlcnQiLCItcmVzaXplIDEwMjR4MTAyNFx1MDAzZSJdXQ.jpg?sha=e47c3b5df9258394 | N7: Floor 4, 417
A8: 1825 | B8: Juicy Salif Lemon Squeezer | C8: 8418 | D8: {=_xlfn.TEXTJOIN(",",TRUE,_xlfn.XLOOKUP(_xlfn.TEXTSPLIT(C8,",")*1,_xlfn._TRO_TRAILING(Artists!A:A),_xlfn._TRO_TRAILING(Artists!B:B)))} -> Philippe Starck | E8: 1988 | F8: {=_xlfn.REGEXEXTRACT(E8,"\d{4}")*1} -> 1988 | G8: P.T.F.E.-treated pressure cast aluminum and polyamide | H8: 11 1/2 x 5" (29.2 x 12.7 cm) | I8: Design | J8: Architecture & Design | K8: 36544 | L8: https://www.moma.org/collection/works/1825 | M8: https://www.moma.org/media/W1siZiIsIjIxMDExNyJdLFsicCIsImNvbnZlcnQiLCItcmVzaXplIDEwMjR4MTAyNFx1MDAzZSJdXQ.jpg?sha=1b9d4471735839d3 | N8: Floor 1, 1 South
A9: 1911 | B9: Max-2 Stacking Cups | C9: 6155 | D9: {=_xlfn.TEXTJOIN(",",TRUE,_xlfn.XLOOKUP(_xlfn.TEXTSPLIT(C9,",")*1,_xlfn._TRO_TRAILING(Artists!A:A),_xlfn._TRO_TRAILING(Artists!B:B)))} -> Massimo Vignelli | E9: 1970 | F9: {=_xlfn.REGEXEXTRACT(E9,"\d{4}")*1} -> 1970 | G9: Plastic | H9: Each: 2 3/4 x 6 1/4 x 7 1/2" (7 x 15.9 x 19.1 cm) | I9: Design | J9: Architecture & Design | K9: 26400 | L9: https://www.moma.org/collection/works/1911 | M9: https://www.moma.org/media/W1siZiIsIjIxMDE0OSJdLFsicCIsImNvbnZlcnQiLCItcmVzaXplIDEwMjR4MTAyNFx1MDAzZSJdXQ.jpg?sha=bd4f4bc76f2d531e | N9: Floor 1, 1 South
A10: 1964 | B10: Tilt-Back Side Chair | C10: 1671, 1672 | D10: {=_xlfn.TEXTJOIN(",",TRUE,_xlfn.XLOOKUP(_xlfn.TEXTSPLIT(C10,",")*1,_xlfn._TRO_TRAILING(Artists!A:A),_xlfn._TRO_TRAILING(Artists!B:B)))} -> Charles Eames,Ray Eames | E10: c. 1944 | F10: {=_xlfn.REGEXEXTRACT(E10,"\d{4}")*1} -> 1944 | G10: Molded plywood, metal rod, rubber shockmounts, and rubber glides | H10: 25 3/4 x 20 x 29" (65.4 x 50.8 x 73.7 cm) | I10: Design | J10: Architecture & Design | K10: 16929 | L10: https://www.moma.org/collection/works/1964 | M10: https://www.moma.org/media/W1siZiIsIjIyNjM3MyJdLFsicCIsImNvbnZlcnQiLCItcmVzaXplIDEwMjR4MTAyNFx1MDAzZSJdXQ.jpg?sha=16733e2d84824824 | N10: Floor 1, 1 South
A11: 2067 | B11: Little River | C11: 5814 | D11: {=_xlfn.TEXTJOIN(",",TRUE,_xlfn.XLOOKUP(_xlfn.TEXTSPLIT(C11,",")*1,_xlfn._TRO_TRAILING(Artists!A:A),_xlfn._TRO_TRAILING(Artists!B:B)))} -> Lenore Tawney | E11: 1968 | F11: {=_xlfn.REGEXEXTRACT(E11,"\d{4}")*1} -> 1968 | G11: Linen | H11: 91 1/2 x 21" (232.4 x 53.3 cm) | I11: Design | J11: Architecture & Design | L11: https://www.moma.org/collection/works/2067 | M11: https://www.moma.org/media/W1siZiIsIjM5MTE5NSJdLFsicCIsImNvbnZlcnQiLCItcmVzaXplIDEwMjR4MTAyNFx1MDAzZSJdXQ.jpg?sha=19d84324c8dea7de | N11: Floor 5, 516
A12: 2133 | B12: Prototype for Chaise Longue (La Chaise) | C12: 1671, 1672 | D12: {=_xlfn.TEXTJOIN(",",TRUE,_xlfn.XLOOKUP(_xlfn.TEXTSPLIT(C12,",")*1,_xlfn._TRO_TRAILING(Artists!A:A),_xlfn._TRO_TRAILING(Artists!B:B)))} -> Charles Eames,Ray Eames | E12: 1948 | F12: {=_xlfn.REGEXEXTRACT(E12,"\d{4}")*1} -> 1948 | G12: Hard rubber foam, plastic, wood, and metal | H12: 32 1/2 x 59 x 34 1/4" (82.5 x 149.8 x 87 cm) | I12: Design | J12: Architecture & Design | K12: 26792 | L12: https://www.moma.org/collection/works/2133 | M12: https://www.moma.org/media/W1siZiIsIjIxMjEwNCJdLFsicCIsImNvbnZlcnQiLCItcmVzaXplIDEwMjR4MTAyNFx1MDAzZSJdXQ.jpg?sha=a829eced7842c23c | N12: Floor 1, 1 South
A13: 2200 | B13: Pitcher | C13: 1968 | D13: {=_xlfn.TEXTJOIN(",",TRUE,_xlfn.XLOOKUP(_xlfn.TEXTSPLIT(C13,",")*1,_xlfn._TRO_TRAILING(Artists!A:A),_xlfn._TRO_TRAILING(Artists!B:B)))} -> Kaj Franck | E13: 1954 | F13: {=_xlfn.REGEXEXTRACT(E13,"\d{4}")*1} -> 1954 | G13: Turn mold-blown glass | H13: h. 8 3/4" (22.2 cm), diam. 3 7/8" (9.9 cm) | I13: Design | J13: Architecture & Design | K13: 33618 | L13: https://www.moma.org/collection/works/2200 | M13: https://www.moma.org/media/W1siZiIsIjIyODAxMiJdLFsicCIsImNvbnZlcnQiLCItcmVzaXplIDEwMjR4MTAyNFx1MDAzZSJdXQ.jpg?sha=14397e948a30d891 | N13: Floor 1, 1 South
A14: 2205 | B14: Tumblers | C14: 1968 | D14: {=_xlfn.TEXTJOIN(",",TRUE,_xlfn.XLOOKUP(_xlfn.TEXTSPLIT(C14,",")*1,_xlfn._TRO_TRAILING(Artists!A:A),_xlfn._TRO_TRAILING(Artists!B:B)))} -> Kaj Franck | E14: 1954 | F14: {=_xlfn.REGEXEXTRACT(E14,"\d{4}")*1} -> 1954 | G14: Turn mold-blown glass | H14: Each: 3 1/4 x 3 1/8" (8.3 x 8 cm) | I14: Design | J14: Architecture & Design | K14: 33618 | L14: https://www.moma.org/collection/works/2205 | M14: https://www.moma.org/media/W1siZiIsIjIyODAxMyJdLFsicCIsImNvbnZlcnQiLCItcmVzaXplIDEwMjR4MTAyNFx1MDAzZSJdXQ.jpg?sha=6e69bbb923df7620 | N14: Floor 1, 1 South
A15: 2234 | B15: Bell-47D1 Helicopter | C15: 6518 | D15: {=_xlfn.TEXTJOIN(",",TRUE,_xlfn.XLOOKUP(_xlfn.TEXTSPLIT(C15,",")*1,_xlfn._TRO_TRAILING(Artists!A:A),_xlfn._TRO_TRAILING(Artists!B:B)))} -> Arthur Young | E15: 1945 | F15: {=_xlfn.REGEXEXTRACT(E15,"\d{4}")*1} -> 1945 | G15: Aluminum, steel, and acrylic plastic | H15: 9' 2 3/4" x 7' 11" x 42' 8 3/4" (281.3 x 302 x 1271.9 cm) | I15: Design | J15: Architecture & Design | K15: 30985 | L15: https://www.moma.org/collection/works/2234 | M15: https://www.moma.org/media/W1siZiIsIjI0ODkwMCJdLFsicCIsImNvbnZlcnQiLCItcmVzaXplIDEwMjR4MTAyNFx1MDAzZSJdXQ.jpg?sha=1e29acec814a8870 | N15: Floor 3
A16: 2267 | B16: Dark River | C16: 5814 | D16: {=_xlfn.TEXTJOIN(",",TRUE,_xlfn.XLOOKUP(_xlfn.TEXTSPLIT(C16,",")*1,_xlfn._TRO_TRAILING(Artists!A:A),_xlfn._TRO_TRAILING(Artists!B:B)))} -> Lenore Tawney | E16: 1962 | F16: {=_xlfn.REGEXEXTRACT(E16,"\d{4}")*1} -> 1962 | G16: Linen and wood | H16: 164 x 22 1/2" (416.6 x 57.2 cm) | I16: Design | J16: Architecture & Design | K16: 23055 | L16: https://www.moma.org/collection/works/2267 | M16: https://www.moma.org/media/W1siZiIsIjI4NDc1MCJdLFsicCIsImNvbnZlcnQiLCItcmVzaXplIDEwMjR4MTAyNFx1MDAzZSJdXQ.jpg?sha=e0591a2e13829cbe | N16: Floor 1
A17: 2294 | B17: Side Chair (model DCMU) | C17: 1671, 1672 | D17: {=_xlfn.TEXTJOIN(",",TRUE,_xlfn.XLOOKUP(_xlfn.TEXTSPLIT(C17,",")*1,_xlfn._TRO_TRAILING(Artists!A:A),_xlfn._TRO_TRAILING(Artists!B:B)))} -> Charles Eames,Ray Eames | E17: 1969 | F17: {=_xlfn.REGEXEXTRACT(E17,"\d{4}")*1} -> 1969 | G17: Polyester reinforced with glass fibers, steel tube, Naugahyde with polyurethane foam padding, vinyl, and nylon | H17: Each: 29 1/2 x 19 1/2 x 21 1/2" (74.9 x 49.5 x 54.6 cm) | I17: Design | J17: Architecture & Design | K17: 26792 | L17: https://www.moma.org/collection/works/2294 | M17: https://www.moma.org/media/W1siZiIsIjIyODQzNCJdLFsicCIsImNvbnZlcnQiLCItcmVzaXplIDEwMjR4MTAyNFx1MDAzZSJdXQ.jpg?sha=e89eae257b2fbd95 | N17: Floor 1, 1 South
A18: 2334 | B18: Child's cradle (model 1573) | C18: 8182, 8845, 10582 | D18: {=_xlfn.TEXTJOIN(",",TRUE,_xlfn.XLOOKUP(_xlfn.TEXTSPLIT(C18,",")*1,_xlfn._TRO_TRAILING(Artists!A:A),_xlfn._TRO_TRAILING(Artists!B:B)))} -> Josef Kohn,Jacob Kohn,J. & J. Kohn, Vienna | E18: c. 1895 | F18: {=_xlfn.REGEXEXTRACT(E18,"\d{4}")*1} -> 1895 | G18: Ebonized bent beechwood | H18: 80 1/4 x 56 1/4 x 25 7/16" (203.8 x 142.9 x 64.6 cm) | I18: Design | J18: Architecture & Design | K18: 34093 | L18: https://www.moma.org/collection/works/2334 | M18: https://www.moma.org/media/W1siZiIsIjIxMDUyNSJdLFsicCIsImNvbnZlcnQiLCItcmVzaXplIDEwMjR4MTAyNFx1MDAzZSJdXQ.jpg?sha=b953728b4dac2621 | N18: Floor 5, 504
A19: 2363 | B19: Vase | C19: 9682 | D19: {=_xlfn.TEXTJOIN(",",TRUE,_xlfn.XLOOKUP(_xlfn.TEXTSPLIT(C19,",")*1,_xlfn._TRO_TRAILING(Artists!A:A),_xlfn._TRO_TRAILING(Artists!B:B)))} -> Daum Frères, Nancy, France | E19: c. 1900 | F19: {=_xlfn.REGEXEXTRACT(E19,"\d{4}")*1} -> 1900 | G19: Hand-painted sculptured glass | H19: 21 1/2 × 4 3/8 × 4 1/4" (54.6 × 11.1 × 10.8 cm) | I19: Design | J19: Architecture & Design | K19: 21523 | L19: https://www.moma.org/collection/works/2363 | M19: https://www.moma.org/media/W1siZiIsIjU1NjIwMyJdLFsicCIsImNvbnZlcnQiLCItcmVzaXplIDEwMjR4MTAyNFx1MDAzZSJdXQ.jpg?sha=7a3c71ef95e440e1 | N19: Floor 5, 501
A20: 2368 | B20: Le Parthènon Vase | C20: 9682 | D20: {=_xlfn.TEXTJOIN(",",TRUE,_xlfn.XLOOKUP(_xlfn.TEXTSPLIT(C20,",")*1,_xlfn._TRO_TRAILING(Artists!A:A),_xlfn._TRO_TRAILING(Artists!B:B)))} -> Daum Frères, Nancy, France | E20: c. 1900 | F20: {=_xlfn.REGEXEXTRACT(E20,"\d{4}")*1} -> 1900 | G20: Painted glass | H20: 15 3/16 × 3 1/4 × 3 1/2" (38.6 × 8.3 × 8.9 cm) | I20: Design | J20: Architecture & Design | K20: 21523 | L20: https://www.moma.org/collection/works/2368 | M20: https://www.moma.org/media/W1siZiIsIjIyODUxMiJdLFsicCIsImNvbnZlcnQiLCItcmVzaXplIDEwMjR4MTAyNFx1MDAzZSJdXQ.jpg?sha=558a588d4e27c5cd | N20: Floor 5, 501
A21: 2373 | B21: Vase | C21: 9682 | D21: {=_xlfn.TEXTJOIN(",",TRUE,_xlfn.XLOOKUP(_xlfn.TEXTSPLIT(C21,",")*1,_xlfn._TRO_TRAILING(Artists!A:A),_xlfn._TRO_TRAILING(Artists!B:B)))} -> Daum Frères, Nancy, France | E21: c. 1900 | F21: {=_xlfn.REGEXEXTRACT(E21,"\d{4}")*1} -> 1900 | G21: Painted glass | H21: 18 1/8 × 3 1/4 × 2 1/2" (46 × 8.3 × 6.4 cm) | I21: Design | J21: Architecture & Design | K21: 21523 | L21: https://www.moma.org/collection/works/2373 | M21: https://www.moma.org/media/W1siZiIsIjIyODUxOSJdLFsicCIsImNvbnZlcnQiLCItcmVzaXplIDEwMjR4MTAyNFx1MDAzZSJdXQ.jpg?sha=e351bfe7021e1a18 | N21: Floor 5, 501
A22: 2377 | B22: Vase | C22: 9682 | D22: {=_xlfn.TEXTJOIN(",",TRUE,_xlfn.XLOOKUP(_xlfn.TEXTSPLIT(C22,",")*1,_xlfn._TRO_TRAILING(Artists!A:A),_xlfn._TRO_TRAILING(Artists!B:B)))} -> Daum Frères, Nancy, France | E22: c. 1900 | F22: {=_xlfn.REGEXEXTRACT(E22,"\d{4}")*1} -> 1900 | G22: Painted glass | H22: 8 1/4 x 3 1/2 x 2 3/4" (21 x 8.9 x 7 cm) | I22: Design | J22: Architecture & Design | K22: 21523 | L22: https://www.moma.org/collection/works/2377 | M22: https://www.moma.org/media/W1siZiIsIjIxMDU1NiJdLFsicCIsImNvbnZlcnQiLCItcmVzaXplIDEwMjR4MTAyNFx1MDAzZSJdXQ.jpg?sha=8fe2792e391d8c24 | N22: Floor 5, 501
A23: 2381 | B23: Miniature Vase | C23: 9682 | D23: {=_xlfn.TEXTJOIN(",",TRUE,_xlfn.XLOOKUP(_xlfn.TEXTSPLIT(C23,",")*1,_xlfn._TRO_TRAILING(Artists!A:A),_xlfn._TRO_TRAILING(Artists!B:B)))} -> Daum Frères, Nancy, France | E23: c. 1900 | F23: {=_xlfn.REGEXEXTRACT(E23,"\d{4}")*1} -> 1900 | G23: Painted glass | H23: 5 7/8 × 1 7/8 × 1 7/8" (14.9 × 4.8 × 4.8 cm) | I23: Design | J23: Architecture & Design | K23: 21523 | L23: https://www.moma.org/collection/works/2381 | M23: https://www.moma.org/media/W1siZiIsIjIyODUyMyJdLFsicCIsImNvbnZlcnQiLCItcmVzaXplIDEwMjR4MTAyNFx1MDAzZSJdXQ.jpg?sha=4000408274c1db9c | N23: Floor 5, 501
A24: 2384 | B24: Miniature Vase | C24: 9682 | D24: {=_xlfn.TEXTJOIN(",",TRUE,_xlfn.XLOOKUP(_xlfn.TEXTSPLIT(C24,",")*1,_xlfn._TRO_TRAILING(Artists!A:A),_xlfn._TRO_TRAILING(Artists!B:B)))} -> Daum Frères, Nancy, France | E24: c. 1900 | F24: {=_xlfn.REGEXEXTRACT(E24,"\d{4}")*1} -> 1900 | G24: Hand-painted sculptured glass | H24: 6 × 2 × 2" (15.2 × 5.1 × 5.1 cm) | I24: Design | J24: Architecture & Design | K24: 21523 | L24: https://www.moma.org/collection/works/2384 | M24: https://www.moma.org/media/W1siZiIsIjIyODU5NyJdLFsicCIsImNvbnZlcnQiLCItcmVzaXplIDEwMjR4MTAyNFx1MDAzZSJdXQ.jpg?sha=57006abd13064ad0 | N24: Floor 5, 501
A25: 2393 | B25: Entrance Gate to Paris Subway (Métropolitain) Station, Paris, France | C25: 2407 | D25: {=_xlfn.TEXTJOIN(",",TRUE,_xlfn.XLOOKUP(_xlfn.TEXTSPLIT(C25,",")*1,_xlfn._TRO_TRAILING(Artists!A:A),_xlfn._TRO_TRAILING(Artists!B:B)))} -> Hector Guimard | E25: c. 1900 | F25: {=_xlfn.REGEXEXTRACT(E25,"\d{4}")*1} -> 1900 | G25: Painted cast iron, glazed lava, and glass | H25: 13' 11" x 17' 10" x 32" (424.2 x 543.6 x 81.3 cm)_x000D_ Each vertical stanchion: 1040 lbs. Horizontal component: 460 lbs. Glazed lava sign: 100 lbs. | I25: Architecture | J25: Architecture & Design | K25: 21523 | L25: https://www.moma.org/collection/works/2393 | M25: https://www.moma.org/media/W1siZiIsIjI0MDYzNCJdLFsicCIsImNvbnZlcnQiLCItcmVzaXplIDEwMjR4MTAyNFx1MDAzZSJdXQ.jpg?sha=9ec928b17dd8619b | N25: Floor 1, Sculpture Garden
A26: 2565 | B26: Tulip Armchair (model 150) | C26: 5103 | D26: {=_xlfn.TEXTJOIN(",",TRUE,_xlfn.XLOOKUP(_xlfn.TEXTSPLIT(C26,",")*1,_xlfn._TRO_TRAILING(Artists!A:A),_xlfn._TRO_TRAILING(Artists!B:B)))} -> Eero Saarinen | E26: 1955-56 | F26: {=_xlfn.REGEXEXTRACT(E26,"\d{4}")*1} -> 1955 | G26: Fiberglass-reinforced polyester and cast aluminum | H26: 31 1/2 x 25 1/4 x 23 1/2" (80 x 64.1 x 59.7 cm) | I26: Design | J26: Architecture & Design | K26: 21523 | L26: https://www.moma.org/collection/works/2565 | M26: https://www.moma.org/media/W1siZiIsIjUxNzkwNCJdLFsicCIsImNvbnZlcnQiLCItcmVzaXplIDEwMjR4MTAyNFx1MDAzZSJdXQ.jpg?sha=c735b3f62bac1931 | N26: Floor 1, 1 South
A27: 2659 | B27: Bearing Spring | C27: 9953 | D27: {=_xlfn.TEXTJOIN(",",TRUE,_xlfn.XLOOKUP(_xlfn.TEXTSPLIT(C27,",")*1,_xlfn._TRO_TRAILING(Artists!A:A),_xlfn._TRO_TRAILING(Artists!B:B)))} -> American Steel & Wire Co., Worcester, MA | E27: Before 1934 | F27: {=_xlfn.REGEXEXTRACT(E27,"\d{4}")*1} -> 1934 | G27: Steel | H27: 2 1/2 x 1 5/16" (6.4 x 3.4 cm) | I27: Design | J27: Architecture & Design | K27: 12510 | L27: https://www.moma.org/collection/works/2659 | M27: https://www.moma.org/media/W1siZiIsIjIxMDY4NyJdLFsicCIsImNvbnZlcnQiLCItcmVzaXplIDEwMjR4MTAyNFx1MDAzZSJdXQ.jpg?sha=f6c14e8dd33a4ac4 | N27: Floor 5, 511
A28: 2682 | B28: Self-Aligning Ball Bearing | C28: 6394 | D28: {=_xlfn.TEXTJOIN(",",TRUE,_xlfn.XLOOKUP(_xlfn.TEXTSPLIT(C28,",")*1,_xlfn._TRO_TRAILING(Artists!A:A),_xlfn._TRO_TRAILING(Artists!B:B)))} -> Sven Wingquist | E28: 1907 | F28: {=_xlfn.REGEXEXTRACT(E28,"\d{4}")*1} -> 1907 | G28: Chrome-plated steel | H28: 1 3/4 x 8 1/2" (4.4 x 21.6 cm) | I28: Design | J28: Architecture & Design | K28: 12510 | L28: https://www.moma.org/collection/works/2682 | M28: https://www.moma.org/media/W1siZiIsIjIxMDcwMCJdLFsicCIsImNvbnZlcnQiLCItcmVzaXplIDEwMjR4MTAyNFx1MDAzZSJdXQ.jpg?sha=805516127e63e161 | N28: Floor 5, 511
A29: 2704 | B29: Flush Valve | C29: 10121 | D29: {=_xlfn.TEXTJOIN(",",TRUE,_xlfn.XLOOKUP(_xlfn.TEXTSPLIT(C29,",")*1,_xlfn._TRO_TRAILING(Artists!A:A),_xlfn._TRO_TRAILING(Artists!B:B)))} -> Scovill Mfg. Co., Plumbers Brass Goods Div., Waterbury, CT | E29: Before 1934 | F29: {=_xlfn.REGEXEXTRACT(E29,"\d{4}")*1} -> 1934 | G29: Chromium | H29: 13 3/8 × 12 × 3 3/4" (34 × 30.5 × 9.5 cm) | I29: Design | J29: Architecture & Design | K29: 12420 | L29: https://www.moma.org/collection/works/2704 | M29: https://www.moma.org/media/W1siZiIsIjIxMDcxMiJdLFsicCIsImNvbnZlcnQiLCItcmVzaXplIDEwMjR4MTAyNFx1MDAzZSJdXQ.jpg?sha=b1f0b041fbdb5455 | N29: Floor 5, 511
A30: 2728 | B30: Akari Floor Lamp (model 2P) | C30: 4324 | D30: {=_xlfn.TEXTJOIN(",",TRUE,_xlfn.XLOOKUP(_xlfn.TEXTSPLIT(C30,",")*1,_xlfn._TRO_TRAILING(Artists!A:A),_xlfn._TRO_TRAILING(Artists!B:B)))} -> Isamu Noguchi | E30: c. 1968 | F30: {=_xlfn.REGEXEXTRACT(E30,"\d{4}")*1} -> 1968 | G30: Paper shade and metal frame | H30: h. 30" (76.2 cm) | I30: Design | J30: Architecture & Design | K30: 28548 | L30: https://www.moma.org/collection/works/2728 | M30: https://www.moma.org/media/W1siZiIsIjIyODgwOSJdLFsicCIsImNvbnZlcnQiLCItcmVzaXplIDEwMjR4MTAyNFx1MDAzZSJdXQ.jpg?sha=cf7fba4d2ac5f3b6 | N30: Floor 1, 1 South
A31: 2731 | B31: Steel Balls | C31: 10113 | D31: {=_xlfn.TEXTJOIN(",",TRUE,_xlfn.XLOOKUP(_xlfn.TEXTSPLIT(C31,",")*1,_xlfn._TRO_TRAILING(Artists!A:A),_xlfn._TRO_TRAILING(Artists!B:B)))} -> S.K.F. Industries, Inc., Hartford, CT | E31: Before 1934 | F31: {=_xlfn.REGEXEXTRACT(E31,"\d{4}")*1} -> 1934 | G31: Nickel-plated steel | H31: Dimensions range from a minimum diameter of 3/8" (1 cm) to a max diameter of 1" (2.5 cm) | I31: Design | J31: Architecture & Design | K31: 12510 | L31: https://www.moma.org/collection/works/2731 | M31: https://www.moma.org/media/W1siZiIsIjIxMDcyOSJdLFsicCIsImNvbnZlcnQiLCItcmVzaXplIDEwMjR4MTAyNFx1MDAzZSJdXQ.jpg?sha=80b58dcb7f6b0c95 | N31: Floor 5, 511
A32: 2805 | B32: Boiling Flasks | C32: 1249 | D32: {=_xlfn.TEXTJOIN(",",TRUE,_xlfn.XLOOKUP(_xlfn.TEXTSPLIT(C32,",")*1,_xlfn._TRO_TRAILING(Artists!A:A),_xlfn._TRO_TRAILING(Artists!B:B)))} -> Corning Glass Works, Corning, NY | E32: 1920s | F32: {=_xlfn.REGEXEXTRACT(E32,"\d{4}")*1} -> 1920 | G32: Borosilicate glass | H32: .1: 14 5/8 x 9 1/2" (37.2 x 24.1 cm)_x000D_ .2: 7 x 4" (17.8 x 10.2 cm)_x000D_ .4: 8 1/2 x 5 1/8" (21.6 x 13 cm)_x000D_ .5-.6: 5 5/8 x 3 1/4" (14.3 x 8.2 cm) | I32: Design | J32: Architecture & Design | K32: 12510 | L32: https://www.moma.org/collection/works/2805 | M32: https://www.moma.org/media/W1siZiIsIjIxMDc2MCJdLFsicCIsImNvbnZlcnQiLCItcmVzaXplIDEwMjR4MTAyNFx1MDAzZSJdXQ.jpg?sha=a19a047dbf5a1b7a | N32: Floor 5, 511
A33: 2807 | B33: Chess Set | C33: 3716 | D33: {=_xlfn.TEXTJOIN(",",TRUE,_xlfn.XLOOKUP(_xlfn.TEXTSPLIT(C33,",")*1,_xlfn._TRO_TRAILING(Artists!A:A),_xlfn._TRO_TRAILING(Artists!B:B)))} -> Man Ray (Emmanuel Radnitzky) | E33: 1920–1926 | F33: {=_xlfn.REGEXEXTRACT(E33,"\d{4}")*1} -> 1920 | G33: Silver-plated and oxidized silver-plated brass | H33: Tallest piece: h. 4" (10.2 cm)_x000D_ Case: 2 5/8 x 21 1/4 x 16 1/2" (6.7 x 54 x 41.9 cm) | I33: Design | J33: Architecture & Design | K33: 18422 | L33: https://www.moma.org/collection/works/2807 | M33: https://www.moma.org/media/W1siZiIsIjI1Mjc1OSJdLFsicCIsImNvbnZlcnQiLCItcmVzaXplIDEwMjR4MTAyNFx1MDAzZSJdXQ.jpg?sha=9d8ac151caf39fee | N33: Floor 5, 513
A34: 2816 | B34: Beakers | C34: 9339 | D34: {=_xlfn.TEXTJOIN(",",TRUE,_xlfn.XLOOKUP(_xlfn.TEXTSPLIT(C34,",")*1,_xlfn._TRO_TRAILING(Artists!A:A),_xlfn._TRO_TRAILING(Artists!B:B)))} -> Coors Porcelain Co., Golden, CO | E34: 1920s | F34: {=_xlfn.REGEXEXTRACT(E34,"\d{4}")*1} -> 1920 | G34: Glazed porcelain | H34: .1: 8 3/8 x 5 3/8" (21.2 x 13.7 cm)_x000D_ .3: 6 1/2 x 4 1/4" (16.5 x 10.8 cm)_x000D_ .4: 6 x 3 7/8" (15.2 x 9.8 cm)_x000D_ .5: 5 5/8 x 3 5/8" (14.3 x 9.2 cm)_x000D_ .7: 4 5/8 x 3 1/8" (11.8 x 7.9 cm)_x000D_ .9: 3 3/4 x 2 1/2" (9.5 x 6.4 cm) | I34: Design | J34: Architecture & Design | K34: 12510 | L34: https://www.moma.org/collection/works/2816 | M34: https://www.moma.org/media/W1siZiIsIjIxMDc2MyJdLFsicCIsImNvbnZlcnQiLCItcmVzaXplIDEwMjR4MTAyNFx1MDAzZSJdXQ.jpg?sha=e509fc25b6553176 | N34: Floor 5, 511
A35: 2841 | B35: Spring | C35: 9953 | D35: {=_xlfn.TEXTJOIN(",",TRUE,_xlfn.XLOOKUP(_xlfn.TEXTSPLIT(C35,",")*1,_xlfn._TRO_TRAILING(Artists!A:A),_xlfn._TRO_TRAILING(Artists!B:B)))} -> American Steel & Wire Co., Worcester, MA | E35: Before 1934 | F35: {=_xlfn.REGEXEXTRACT(E35,"\d{4}")*1} -> 1934 | G35: Steel | H35: 2 1/4 x 2 1/4" (5.7 x 5.7 cm) | I35: Design | J35: Architecture & Design | K35: 12510 | L35: https://www.moma.org/collection/works/2841 | M35: https://www.moma.org/media/W1siZiIsIjIxMDc3OCJdLFsicCIsImNvbnZlcnQiLCItcmVzaXplIDEwMjR4MTAyNFx1MDAzZSJdXQ.jpg?sha=4c83ced717ca1447 | N35: Floor 5, 511
A36: 2859 | B36: Hydrometer Jar | C36: 6011 | D36: {=_xlfn.TEXTJOIN(",",TRUE,_xlfn.XLOOKUP(_xlfn.TEXTSPLIT(C36,",")*1,_xlfn._TRO_TRAILING(Artists!A:A),_xlfn._TRO_TRAILING(Artists!B:B)))} -> Unidentified Designer | E36: Before 1934 | F36: {=_xlfn.REGEXEXTRACT(E36,"\d{4}")*1} -> 1934 | G36: Glass | H36: h. 10" (25.4 cm), diam. 11/16" (1.8 cm); base diam. 1 15/16" (4.9 cm) | I36: Design | J36: Architecture & Design | K36: 12510 | L36: https://www.moma.org/collection/works/2859 | M36: https://www.moma.org/media/W1siZiIsIjIxMDc4NyJdLFsicCIsImNvbnZlcnQiLCItcmVzaXplIDEwMjR4MTAyNFx1MDAzZSJdXQ.jpg?sha=8aff4a542a3efc49 | N36: Floor 5, 511
A37: 2890 | B37: Hydrometer Jar | C37: 6011 | D37: {=_xlfn.TEXTJOIN(",",TRUE,_xlfn.XLOOKUP(_xlfn.TEXTSPLIT(C37,",")*1,_xlfn._TRO_TRAILING(Artists!A:A),_xlfn._TRO_TRAILING(Artists!B:B)))} -> Unidentified Designer | E37: Before 1934 | F37: {=_xlfn.REGEXEXTRACT(E37,"\d{4}")*1} -> 1934 | G37: Glass | H37: 6 3/4 x 1 5/8" (17.2 x 4.2 cm) | I37: Design | J37: Architecture & Design | K37: 12510 | L37: https://www.moma.org/collection/works/2890 | M37: https://www.moma.org/media/W1siZiIsIjIxMDgwOSJdLFsicCIsImNvbnZlcnQiLCItcmVzaXplIDEwMjR4MTAyNFx1MDAzZSJdXQ.jpg?sha=9f8bda1f03a4436c | N37: Floor 5, 511
A38: 2891 | B38: Wear-Ever Tea Kettle (model 1403) | C38: 2402 | D38: {=_xlfn.TEXTJOIN(",",TRUE,_xlfn.XLOOKUP(_xlfn.TEXTSPLIT(C38,",")*1,_xlfn._TRO_TRAILING(Artists!A:A),_xlfn._TRO_TRAILING(Artists!B:B)))} -> Lurelle Guild | E38: c. 1932-33 | F38: {=_xlfn.REGEXEXTRACT(E38,"\d{4}")*1} -> 1932 | G38: Aluminum and plastic | H38: 8 1/2 x 9 1/2" (21.6 x 24.1 cm) | I38: Design | J38: Architecture & Design | K38: 16384 | L38: https://www.moma.org/collection/works/2891 | M38: https://www.moma.org/media/W1siZiIsIjIyODkxMSJdLFsicCIsImNvbnZlcnQiLCItcmVzaXplIDEwMjR4MTAyNFx1MDAzZSJdXQ.jpg?sha=13d364be6a47af30 | N38: Floor 5, 511
A39: 2983 | B39: Flores Box | C39: 3766 | D39: {=_xlfn.TEXTJOIN(",",TRUE,_xlfn.XLOOKUP(_xlfn.TEXTSPLIT(C39,",")*1,_xlfn._TRO_TRAILING(Artists!A:A),_xlfn._TRO_TRAILING(Artists!B:B)))} -> Enzo Mari | E39: 1991 | F39: {=_xlfn.REGEXEXTRACT(E39,"\d{4}")*1} -> 1991 | G39: Thermoplastic polymer | H39: 3 x 12 1/4 x 6" (7.6 x 31.1 x 15.2 cm) | I39: Design | J39: Architecture & Design | K39: 35907 | L39: https://www.moma.org/collection/works/2983 | M39: https://www.moma.org/media/W1siZiIsIjIxMDg1MyJdLFsicCIsImNvbnZlcnQiLCItcmVzaXplIDEwMjR4MTAyNFx1MDAzZSJdXQ.jpg?sha=c087e4e6cd38315f | N39: Floor 1, 1 South
A40: 3025 | B40: Bottles | C40: 10302 | D40: {=_xlfn.TEXTJOIN(",",TRUE,_xlfn.XLOOKUP(_xlfn.TEXTSPLIT(C40,",")*1,_xlfn._TRO_TRAILING(Artists!A:A),_xlfn._TRO_TRAILING(Artists!B:B)))} -> Owens-Illinois Glass Co., Toledo, OH | E40: Before 1934 | F40: {=_xlfn.REGEXEXTRACT(E40,"\d{4}")*1} -> 1934 | G40: Glass and plastic | H40: .1: 6 1/2 x 3 1/4" (16.5 x 8.3 cm)_x000D_ .2: 5 1/4 x 2 3/8" (13.4 x 6 cm)_x000D_ .3: 4 1/4 x 2" (10.8 x 5.1 cm) | I40: Design | J40: Architecture & Design | L40: https://www.moma.org/collection/works/3025 | M40: https://www.moma.org/media/W1siZiIsIjIxMDg2OCJdLFsicCIsImNvbnZlcnQiLCItcmVzaXplIDEwMjR4MTAyNFx1MDAzZSJdXQ.jpg?sha=82554ae87c24eaef | N40: Floor 5, 511
...
